<?xml version="1.0" encoding="utf-8"?>
<!-- This URDF was automatically created by SolidWorks to URDF Exporter! Originally created by Stephen Brawner (brawner@gmail.com) 
     Commit Version: 1.6.0-4-g7f85cfe  Build Version: 1.6.7995.38578
     For more information, please see http://wiki.ros.org/sw_urdf_exporter -->
<robot
  name="urdf_brass23">

  <link name="world"/>
  <joint name="base_joint" type="fixed">
    <parent link="world"/>
    <child link="base_link"/>
    <origin rpy="0 0 0" xyz="0.0 0.0 0.0"/>
  </joint>

  <link
    name="base_link">
    <inertial>
      <origin
        xyz="-0.0195891869935232 -0.0769575203316984 0.0390553333294598"
        rpy="0 0 0" />
      <mass
        value="5.73138441310101" />
      <inertia
        ixx="0.0584695059646706"
        ixy="-0.000622271712138452"
        ixz="-0.000371100221057113"
        iyy="0.0249405833126223"
        iyz="-0.00145789372558152"
        izz="0.0770694774964865" />
    </inertial>
    <visual>
      <origin
        xyz="0 0 0"
        rpy="0 0 0" />
      <geometry>
        <mesh
          filename="package://urdf_brass23/meshes/base_link.STL" />
      </geometry>
      <material
        name="">
        <color
          rgba="0.792156862745098 0.819607843137255 0.933333333333333 1" />
      </material>
    </visual>
    <collision>
      <origin
        xyz="0 0 0"
        rpy="0 0 0" />
      <geometry>
        <mesh
          filename="package://urdf_brass23/meshes/base_link.STL" />
      </geometry>
    </collision>
  </link>
  <link
    name="link_1">
    <inertial>
      <origin
        xyz="-0.00356182087654455 1.38777878078145E-17 -0.00800624245087949"
        rpy="0 0 0" />
      <mass
        value="0.848214016521327" />
      <inertia
        ixx="0.00103959567914763"
        ixy="-2.74670115765387E-19"
        ixz="9.18211312032036E-05"
        iyy="0.00237992295197046"
        iyz="4.75457577451699E-21"
        izz="0.00243448325997905" />
    </inertial>
    <visual>
      <origin
        xyz="0 0 0"
        rpy="0 0 0" />
      <geometry>
        <mesh
          filename="package://urdf_brass23/meshes/link_1.STL" />
      </geometry>
      <material
        name="">
        <color
          rgba="0.792156862745098 0.819607843137255 0.933333333333333 1" />
      </material>
    </visual>
    <collision>
      <origin
        xyz="0 0 0"
        rpy="0 0 0" />
      <geometry>
        <mesh
          filename="package://urdf_brass23/meshes/link_1.STL" />
      </geometry>
    </collision>
  </link>
  <joint
    name="joint_base_link1"
    type="revolute">
    <origin
      xyz="0 0 0.1413"
      rpy="0 0 0" />
    <parent
      link="base_link" />
    <child
      link="link_1" />
    <axis
      xyz="0 0 -1" />
    <limit
      lower="-3.14"
      upper="3.14"
      effort="300"
      velocity="3" />
  </joint>
  <link
    name="link_2">
    <inertial>
      <origin
        xyz="-1.11022302462516E-16 0 0.2115"
        rpy="0 0 0" />
      <mass
        value="1.39301428762465" />
      <inertia
        ixx="0.0266408532435391"
        ixy="1.11457323264441E-19"
        ixz="9.44587968972521E-18"
        iyy="0.0269479441638445"
        iyz="-6.98781372432547E-20"
        izz="0.000736371489941689" />
    </inertial>
    <visual>
      <origin
        xyz="0 0 0"
        rpy="0 0 0" />
      <geometry>
        <mesh
          filename="package://urdf_brass23/meshes/link_2.STL" />
      </geometry>
      <material
        name="">
        <color
          rgba="0.792156862745098 0.819607843137255 0.933333333333333 1" />
      </material>
    </visual>
    <collision>
      <origin
        xyz="0 0 0"
        rpy="0 0 0" />
      <geometry>
        <mesh
          filename="package://urdf_brass23/meshes/link_2.STL" />
      </geometry>
    </collision>
  </link>
  <joint
    name="joint_link12"
    type="revolute">
    <origin
      xyz="0.06 0 0.019105"
      rpy="0 0 0" />
    <parent
      link="link_1" />
    <child
      link="link_2" />
    <axis
      xyz="0 1 0" />
    <limit
      lower="-0.0678"
      upper="1.57"
      effort="300"
      velocity="3" />
  </joint>
  <link
    name="link_3">
    <inertial>
      <origin
        xyz="0.137320910394112 -0.03457682365094 -0.000678095028483316"
        rpy="0 0 0" />
      <mass
        value="1.02500185175382" />
      <inertia
        ixx="0.000525009775022775"
        ixy="-2.15000546515497E-06"
        ixz="-0.000266801984813287"
        iyy="0.0107059373115838"
        iyz="-1.15089425773388E-07"
        izz="0.0107034550616419" />
    </inertial>
    <visual>
      <origin
        xyz="0 0 0"
        rpy="0 0 0" />
      <geometry>
        <mesh
          filename="package://urdf_brass23/meshes/link_3.STL" />
      </geometry>
      <material
        name="">
        <color
          rgba="0.792156862745098 0.819607843137255 0.933333333333333 1" />
      </material>
    </visual>
    <collision>
      <origin
        xyz="0 0 0"
        rpy="0 0 0" />
      <geometry>
        <mesh
          filename="package://urdf_brass23/meshes/link_3.STL" />
      </geometry>
    </collision>
  </link>
  <joint
    name="joint_link23"
    type="revolute">
    <origin
      xyz="0 -0.014412 0.423"
      rpy="0 0 0" />
    <parent
      link="link_2" />
    <child
      link="link_3" />
    <axis
      xyz="0 1 0" />
    <limit
      lower="-3.5"
      upper="0.47"
      effort="300"
      velocity="3" />
  </joint>
  <link
    name="link_4">
    <inertial>
      <origin
        xyz="0.0812648935995959 -0.0339716345103549 -0.000337970756351835"
        rpy="0 0 0" />
      <mass
        value="0.315715418364091" />
      <inertia
        ixx="0.000345424808414422"
        ixy="-3.93247408498288E-07"
        ixz="7.45108952662568E-07"
        iyy="0.000377121844568275"
        iyz="-6.32459247591559E-09"
        izz="0.000522765459090098" />
    </inertial>
    <visual>
      <origin
        xyz="0 0 0"
        rpy="0 0 0" />
      <geometry>
        <mesh
          filename="package://urdf_brass23/meshes/link_4.STL" />
      </geometry>
      <material
        name="">
        <color
          rgba="0.792156862745098 0.819607843137255 0.933333333333333 1" />
      </material>
    </visual>
    <collision>
      <origin
        xyz="0 0 0"
        rpy="0 0 0" />
      <geometry>
        <mesh
          filename="package://urdf_brass23/meshes/link_4.STL" />
      </geometry>
    </collision>
  </link>
  <joint
    name="joint_link34"
    type="revolute">
    <origin
      xyz="0.32206 0 0.0092107"
      rpy="0 0 0" />
    <parent
      link="link_3" />
    <child
      link="link_4" />
    <axis
      xyz="0 1 0" />
    <limit
      lower="-2"
      upper="2"
      effort="300"
      velocity="3" />
  </joint>
  <link
    name="end_effector">
    <inertial>
      <origin
        xyz="0.0270974503430043 5.55111512312578E-17 0"
        rpy="0 0 0" />
      <mass
        value="0.0433772870836576" />
      <inertia
        ixx="3.74711243635196E-05"
        ixy="-4.1001365407184E-20"
        ixz="1.30760711232383E-20"
        iyy="2.58699540224155E-05"
        iyz="1.17537053137252E-20"
        izz="4.93701113133164E-05" />
    </inertial>
    <visual>
      <origin
        xyz="0 0 0"
        rpy="0 0 0" />
      <geometry>
        <mesh
          filename="package://urdf_brass23/meshes/end_effector.STL" />
      </geometry>
      <material
        name="">
        <color
          rgba="0.792156862745098 0.819607843137255 0.933333333333333 1" />
      </material>
    </visual>
    <collision>
      <origin
        xyz="0 0 0"
        rpy="0 0 0" />
      <geometry>
        <mesh
          filename="package://urdf_brass23/meshes/end_effector.STL" />
      </geometry>
    </collision>
  </link>
  <joint
    name="joint_link4_ee"
    type="revolute">
    <origin
      xyz="0.1189 -0.034038 -0.00049933"
      rpy="0 0.0041123 0" />
    <parent
      link="link_4" />
    <child
      link="end_effector" />
    <axis
      xyz="1 0 0" />
    <limit
      lower="-3.14"
      upper="3.14"
      effort="300"
      velocity="3" />
  </joint>
  <link
    name="link_outer_right">
    <inertial>
      <origin
        xyz="2.04475325560338E-13 -0.02 0.00504999999999994"
        rpy="0 0 0" />
      <mass
        value="0.00436066372423022" />
      <inertia
        ixx="6.76814010778924E-07"
        ixy="5.94814221584996E-18"
        ixz="1.22009140351572E-23"
        iyy="9.49591877535052E-08"
        iyz="-2.03466283798545E-22"
        izz="6.31352558839343E-07" />
    </inertial>
    <visual>
      <origin
        xyz="0 0 0"
        rpy="0 0 0" />
      <geometry>
        <mesh
          filename="package://urdf_brass23/meshes/link_outer_right.STL" />
      </geometry>
      <material
        name="">
        <color
          rgba="0.792156862745098 0.819607843137255 0.933333333333333 1" />
      </material>
    </visual>
    <collision>
      <origin
        xyz="0 0 0"
        rpy="0 0 0" />
      <geometry>
        <mesh
          filename="package://urdf_brass23/meshes/link_outer_right.STL" />
      </geometry>
    </collision>
  </link>
  <joint
    name="joint_ee_outer_right"
    type="revolute">
    <origin
      xyz="0.030526 -0.04522 0"
      rpy="0 0 0" />
    <parent
      link="end_effector" />
    <child
      link="link_outer_right" />
    <axis
      xyz="0 0 1" />
    <limit
      lower="-3.14"
      upper="3.14"
      effort="300"
      velocity="3" />
  </joint>

  <transmission name="base_link_trans">
  <type>transmission_interface/SimpleTransmission</type>
    <joint name="joint_base_link1">
    <hardwareInterface>hardware_interface/PositionJointInterface</hardwareInterface>
    </joint>
    <actuator name="joint_base_link1_motor">
    <hardwareInterface>hardware_interface/PositionJointInterface</hardwareInterface>
        <mechanicalReduction>1</mechanicalReduction>
    </actuator>
  </transmission>

  <transmission name="link_1_trans">
  <type>transmission_interface/SimpleTransmission</type>
    <joint name="joint_link12">
    <hardwareInterface>hardware_interface/PositionJointInterface</hardwareInterface>
    </joint>
    <actuator name="joint_link12_motor">
    <hardwareInterface>hardware_interface/PositionJointInterface</hardwareInterface>
        <mechanicalReduction>1</mechanicalReduction>
    </actuator>
  </transmission>

  <transmission name="link_2_trans">
  <type>transmission_interface/SimpleTransmission</type>
    <joint name="joint_link23">
    <hardwareInterface>hardware_interface/PositionJointInterface</hardwareInterface>
    </joint>
    <actuator name="joint_link23_motor">
    <hardwareInterface>hardware_interface/PositionJointInterface</hardwareInterface>
        <mechanicalReduction>1</mechanicalReduction>
    </actuator>
  </transmission>

  <transmission name="link_3_trans">
  <type>transmission_interface/SimpleTransmission</type>
    <joint name="joint_link34">
    <hardwareInterface>hardware_interface/PositionJointInterface</hardwareInterface>
    </joint>
    <actuator name="joint_link34_motor">
    <hardwareInterface>hardware_interface/PositionJointInterface</hardwareInterface>
        <mechanicalReduction>1</mechanicalReduction>
    </actuator>
  </transmission>

  <transmission name="link_4_trans">
  <type>transmission_interface/SimpleTransmission</type>
    <joint name="joint_link4_ee">
    <hardwareInterface>hardware_interface/PositionJointInterface</hardwareInterface>
    </joint>
    <actuator name="joint_link4_ee_motor">
    <hardwareInterface>hardware_interface/PositionJointInterface</hardwareInterface>
        <mechanicalReduction>1</mechanicalReduction>
    </actuator>
  </transmission>

  <transmission name="link_outer_right_trans">
  <type>transmission_interface/SimpleTransmission</type>
    <joint name="joint_ee_outer_right">
    <hardwareInterface>hardware_interface/PositionJointInterface</hardwareInterface>
    </joint>
    <actuator name="joint_ee_outer_right">
    <hardwareInterface>hardware_interface/PositionJointInterface</hardwareInterface>
        <mechanicalReduction>1</mechanicalReduction>
    </actuator>
  </transmission>

  <gazebo>
    <plugin name="control" filename="libgazebo_ros_control.so">
      <robotNamespace>/</robotNamespace>
    </plugin>
  </gazebo>
  
</robot>